Workbook
Name Lista_Productos: Tabla_Productos[Nombre_Comercial]
Name ListaCategorias: TablaCategorias[Categoria]
Name ListaMateriales: TablaMateriales[Material]
Name ListaSubcategorias: TablaSubcategorias[Subcategoria]

Sheet Configuración
A1: Parámetro | B1: Valor | C1: Descripción
A2: PORC_DESC_CREDITO | B2: 0.2 | C2: Descuento aplicado para calcular 2 y 3 meses (20% del precio a credicontado)
A3: MESES_2_SEMANAS | B3: 8 | C3: Semanas equivalentes a 2 meses
A4: MESES_3_SEMANAS | B4: 12 | C4: Semanas equivalentes a 3 meses
A5: MIN_SEMANAL | B5: 100 | C5: Pago mínimo semanal permitido
A6: REDONDEO_MULT | B6: 10 | C6: Redondeo a múltiplos de (ej. 10 pesos)
A7: LIMITE_2_MESES | B7: 2000 | C7: Si precio crédito es menor a esto, NO aplica 2 meses
A8: LIMITE_3_MESES | B8: 3000 | C8: Si precio crédito es menor a esto, NO aplica 3 meses
A9: MAX_SEMANAS_LARGO | B9: 52 | C9: Máximo de semanas para el abono semanal (largo plazo)
A12: Categoria | B12: Codigo_Categoria | D12: Categoria | E12: Subcategoria | F12: Codigo_Sub | H12: Material | I12: Codigo_Material
A13: Cocina | B13: COC | D13: Cocina | E13: Vaporera | F13: VAP | H13: Alumino | I13: ALU
A14: Mobiliario | B14: MOB | D14: Cocina | E14: Budinera | F14: BUD | H14: Alumino y Teflon | I14: ALUT
A15: Electrodomésticos | B15: ELE | D15: Cocina | E15: Batería | F15: BAT | H15: Acero inoxidable | I15: ACI
A16: Electrónica | B16: ELC | D16: Cocina | E16: Comal | F16: COM | H16: Madera | I16: MAD
A17: Línea blanca | B17: LBL | D17: Cocina | E17: Olla | F17: OLL | H17: Metal | I17: MET
A18: Hogar | B18: HOG | D18: Cocina | E18: Sartén | F18: SAR | H18: Plástico | I18: PSL
A19: Plásticos | B19: PLA | D19: Cocina | E19: Cazo | F19: CAZ | H19: Tubular | I19: TUB
A20: Temporada | B20: TMP | D20: Cocina | E20: Arrocera | F20: ARR | H20: Peltre | I20: PEL
D21: Cocina | E21: Bandejas | F21: BAN | H21: Triple Fuerte | I21: TF
D22: Mobiliario | E22: Mecedora | F22: MEC | H22: Vidrio | I22: VID
D23: Mobiliario | E23: Silla | F23: SIL | H23: Espuma | I23: ESP
D24: Mobiliario | E24: Mesa | F24: MES | H24: Algodón | I24: ALG
D25: Mobiliario | E25: Ropero | F25: ROP
D26: Mobiliario | E26: Cama | F26: CAM
D27: Mobiliario | E27: Litera | F27: LIT
D28: Mobiliario | E28: Comedor | F28: COMD
D29: Mobiliario | E29: Tocador | F29: TOC
D30: Mobiliario | E30: Closet | F30: CLO
D31: Mobiliario | E31: Cajonera | F31: CAJ
D32: Mobiliario | E32: Alacena | F32: ALA
D33: Mobiliario | E33: Banca | F33: BAN
D34: Mobiliario | E34: Reposet | F34: REP
D35: Mobiliario | E35: Sofá | F35: SOF
D36: Mobiliario | E36: Banco | F36: BCO
... D65: Electrónica | E65: Bocina | F65: BOC

Sheet Respuestas de formulario 1
B1: Nombre del producto | C1: Marca | D1: Categoria del producto | E1: Precio a credito | F1: Precio a contado | G1: Precio a 2 meses | H1: Precio a 3 meses | I1: PG semanal a 2 meses | J1: PG semanal a 3 meses | K1: Abono semanal
B2: Vaporera de aluminio 180cm | C2: El abuelo | D2: Cocina | E2: 10900 | F2: 7630 | G2: =IF(I2="NO APLICA","NO APLICA",I2*8) -> 8720 | H2: =IF(J2="NO APLICA","NO APLICA",J2*12) -> 8760 | I2: =IF(E2<2000,"NO APLICA",MAX(CEILING((E2*0.8)/8,10),100)) -> 1090 | J2: =IF(E2<3000,"NO APLICA",MAX(CEILING((E2*0.8)/12,10),100)) -> 730 | K2: =MAX(CEILING(E2/52,10),100) -> 210
B3: Vaporera de aluminio 120cm | C3: El abuelo | D3: Cocina | E3: 5000 | F3: 3500 | G3: =IF(I3="NO APLICA","NO APLICA",I3*8) -> 4000 | H3: =IF(J3="NO APLICA","NO APLICA",J3*12) -> 4080 | I3: =IF(E3<2000,"NO APLICA",MAX(CEILING((E3*0.8)/8,10),100)) -> 500 | J3: =IF(E3<3000,"NO APLICA",MAX(CEILING((E3*0.8)/12,10),100)) -> 340 | K3: =MAX(CEILING(E3/52,10),100) -> 100
B4: Vaporera de aluminio 90cm pintado | C4: El abuelo | D4: Cocina | E4: 4000 | F4: 2800 | G4: =IF(I4="NO APLICA","NO APLICA",I4*8) -> 3200 | H4: =IF(J4="NO APLICA","NO APLICA",J4*12) -> 3240 | I4: =IF(E4<2000,"NO APLICA",MAX(CEILING((E4*0.8)/8,10),100)) -> 400 | J4: =IF(E4<3000,"NO APLICA",MAX(CEILING((E4*0.8)/12,10),100)) -> 270 | K4: =MAX(CEILING(E4/52,10),100) -> 100
B5: Vaporera de aluminio 70cm | C5: El abuelo | D5: Cocina | E5: 3300 | F5: 2310 | G5: =IF(I5="NO APLICA","NO APLICA",I5*8) -> 2640 | H5: =IF(J5="NO APLICA","NO APLICA",J5*12) -> 2640 | I5: =IF(E5<2000,"NO APLICA",MAX(CEILING((E5*0.8)/8,10),100)) -> 330 | J5: =IF(E5<3000,"NO APLICA",MAX(CEILING((E5*0.8)/12,10),100)) -> 220 | K5: =MAX(CEILING(E5/52,10),100) -> 100
B6: Vaporera de aluminio 100cm | C6: Lamex | D6: Cocina | E6: 4000 | F6: 2800 | G6: =IF(I6="NO APLICA","NO APLICA",I6*8) -> 3200 | H6: =IF(J6="NO APLICA","NO APLICA",J6*12) -> 3240 | I6: =IF(E6<2000,"NO APLICA",MAX(CEILING((E6*0.8)/8,10),100)) -> 400 | J6: =IF(E6<3000,"NO APLICA",MAX(CEILING((E6*0.8)/12,10),100)) -> 270 | K6: =MAX(CEILING(E6/52,10),100) -> 100
B7: Vaporera de aluminio 45cm | C7: El abuelo | D7: Cocina | E7: 2500 | F7: 1750 | G7: =IF(I7="NO APLICA","NO APLICA",I7*8) -> 2000 | H7: =IF(J7="NO APLICA","NO APLICA",J7*12) -> NO APLICA | I7: =IF(E7<2000,"NO APLICA",MAX(CEILING((E7*0.8)/8,10),100)) -> 250 | J7: =IF(E7<3000,"NO APLICA",MAX(CEILING((E7*0.8)/12,10),100)) -> NO APLICA | K7: =MAX(CEILING(E7/52,10),100) -> 100
B8: Vaporera de aluminio 34cm | C8: El abuelo | D8: Cocina | E8: 1800 | F8: 1440 | G8: =IF(I8="NO APLICA","NO APLICA",I8*8) -> NO APLICA | H8: =IF(J8="NO APLICA","NO APLICA",J8*12) -> NO APLICA | I8: =IF(E8<2000,"NO APLICA",MAX(CEILING((E8*0.8)/8,10),100)) -> NO APLICA | J8: =IF(E8<3000,"NO APLICA",MAX(CEILING((E8*0.8)/12,10),100)) -> NO APLICA | K8: =MAX(CEILING(E8/52,10),100) -> 100
B9: Juego de vaporera de 3pz de aluminio 34cm maya | C9: El abuelo | D9: Cocina | E9: 3100 | F9: 2170 | G9: =IF(I9="NO APLICA","NO APLICA",I9*8) -> 2480 | H9: =IF(J9="NO APLICA","NO APLICA",J9*12) -> 2520 | I9: =IF(E9<2000,"NO APLICA",MAX(CEILING((E9*0.8)/8,10),100)) -> 310 | J9: =IF(E9<3000,"NO APLICA",MAX(CEILING((E9*0.8)/12,10),100)) -> 210 | K9: =MAX(CEILING(E9/52,10),100) -> 100
B10: Juego básico 1 | C10: El abuelo | D10: Cocina | E10: 3000 | F10: 2100 | G10: =IF(I10="NO APLICA","NO APLICA",I10*8) -> 2400 | H10: =IF(J10="NO APLICA","NO APLICA",J10*12) -> 2400 | I10: =IF(E10<2000,"NO APLICA",MAX(CEILING((E10*0.8)/8,10),100)) -> 300 | J10: =IF(E10<3000,"NO APLICA",MAX(CEILING((E10*0.8)/12,10),100)) -> 200 | K10: =MAX(CEILING(E10/52,10),100) -> 100
B11: Juego básico 2 | C11: El abuelo | D11: Cocina | E11: 3000 | F11: 2100 | G11: =IF(I11="NO APLICA","NO APLICA",I11*8) -> 2400 | H11: =IF(J11="NO APLICA","NO APLICA",J11*12) -> 2400 | I11: =IF(E11<2000,"NO APLICA",MAX(CEILING((E11*0.8)/8,10),100)) -> 300 | J11: =IF(E11<3000,"NO APLICA",MAX(CEILING((E11*0.8)/12,10),100)) -> 200 | K11: =MAX(CEILING(E11/52,10),100) -> 100
B12: Juego de budineras 3pz | C12: El abuelo | D12: Cocina | E12: 2500 | F12: 1750 | G12: =IF(I12="NO APLICA","NO APLICA",I12*8) -> 2000 | H12: =IF(J12="NO APLICA","NO APLICA",J12*12) -> NO APLICA | I12: =IF(E12<2000,"NO APLICA",MAX(CEILING((E12*0.8)/8,10),100)) -> 250 | J12: =IF(E12<3000,"NO APLICA",MAX(CEILING((E12*0.8)/12,10),100)) -> NO APLICA | K12: =MAX(CEILING(E12/52,10),100) -> 100
B13: Juego Vallarta 3pz | C13: El abuelo | D13: Cocina | E13: 3500 | F13: 2450 | G13: =IF(I13="NO APLICA","NO APLICA",I13*8) -> 2800 | H13: =IF(J13="NO APLICA","NO APLICA",J13*12) -> 2880 | I13: =IF(E13<2000,"NO APLICA",MAX(CEILING((E13*0.8)/8,10),100)) -> 350 | J13: =IF(E13<3000,"NO APLICA",MAX(CEILING((E13*0.8)/12,10),100)) -> 240 | K13: =MAX(CEILING(E13/52,10),100) -> 100
... B181: Colchón kingsa Magic | C181: Restonic | D181: Hogar | E181: 15000 | F181: 10500 | G181: =IF(I181="NO APLICA","NO APLICA",I181*8) -> 12000 | H181: =IF(J181="NO APLICA","NO APLICA",J181*12) -> 12000 | I181: =IF(E181<2000,"NO APLICA",MAX(CEILING((E181*0.8)/8,10),100)) -> 1500 | J181: =IF(E181<3000,"NO APLICA",MAX(CEILING((E181*0.8)/12,10),100)) -> 1000 | K181: =MAX(CEILING(E181/52,10),100) -> 290

Sheet Lista_Maestra
A1: Codigo | B1: Categoria | C1: Subcategoria | D1: Material | E1: Codigo_Cat | F1: Codigo_Sub | G1: Codigo_Mat | H1: Nombre_Comercial | I1: Nombre_Interno | J1: Marca | K1: Medida_Modelo | L1: Precio_Contado | M1: Pago_Semanal_1m | N1: Precio_1_meses | O1: Precio_Credito | P1: Aplica_2_meses | Q1: Pago_Semanal_2m | R1: Precio_2_meses | S1: Aplica_3_meses | T1: Pago_Semanal_3m | U1: Precio_3_meses | V1: Abono_Semanal_Largo | W1: Estatus | X1: Fecha_Actualizacion | Y1: Notas
A2: =IF(OR(E2="",F2="",G2=""),"",E2&"-"&F2&"-"&G2&"-"&TEXT(COUNTIFS($E$2:E2,E2,$F$2:F2,F2,$G$2:G2,G2),"000")) -> MOB-SIL-PSL-001 | B2: Mobiliario | C2: Silla | D2: Plástico | E2: =_xlfn.XLOOKUP(B2,Configuración!A:A,Configuración!B:B,"") -> MOB | F2: {=IF($C2="","",_xlfn.XLOOKUP(1,(Configuración!D:D=$B2)*(Configuración!E:E=$C2),Configuración!F:F,""))} -> SIL | G2: =IF($D2="","",_xlfn.XLOOKUP($D2,Configuración!H:H,Configuración!I:I,"")) -> PSL | H2: 4 Sillas Aruba blanca | I2: 4 Sillas Aruba blanca | J2: Duna | L2: 1670 | M2: =MAX(CEILING(L2/4,10),100) -> 420 | N2: =M2*4 -> 1680 | O2: 2380 | P2: =IF($O2<Configuración!$B$7,"NO","SI") -> SI | Q2: =IF($P2="NO","NO APLICA",MAX(CEILING(($O2*(1-Configuración!$B$2))/Configuración!$B$3,Configuración!$B$6),Configuración!$B$5)) -> 240 | R2: =IF($Q2="NO APLICA","NO APLICA",$Q2*Configuración!$B$3) -> 1920 | S2: =IF($O2<Configuración!$B$8,"NO","SI") -> NO | T2: =IF($S2="NO","NO APLICA",MAX(CEILING(($O2*(1-Configuración!$B$2))/Configuración!$B$4,Configuración!$B$6),Configuración!$B$5)) -> NO APLICA | U2: =IF($T2="NO APLICA","NO APLICA",$T2*Configuración!$B$4) -> NO APLICA | V2: =MAX(CEILING($O2/Configuración!$B$9,Configuración!$B$6),Configuración!$B$5) -> 100 | W2: Activo | X2: 46079
A3: =IF(OR(E3="",F3="",G3=""),"",E3&"-"&F3&"-"&G3&"-"&TEXT(COUNTIFS($E$2:E3,E3,$F$2:F3,F3,$G$2:G3,G3),"000")) -> MOB-SIL-PSL-002 | B3: Mobiliario | C3: Silla | D3: Plástico | E3: =_xlfn.XLOOKUP(B3,Configuración!A:A,Configuración!B:B,"") -> MOB | F3: {=IF($C3="","",_xlfn.XLOOKUP(1,(Configuración!D:D=$B3)*(Configuración!E:E=$C3),Configuración!F:F,""))} -> SIL | G3: =IF($D3="","",_xlfn.XLOOKUP($D3,Configuración!H:H,Configuración!I:I,"")) -> PSL | H3: 4 Sillas Aruba gris | I3: 4 Sillas Aruba gris | J3: Duna | L3: 1380 | M3: =MAX(CEILING(L3/4,10),100) -> 350 | N3: =M3*4 -> 1400 | O3: 1980 | P3: =IF($O3<Configuración!$B$7,"NO","SI") -> NO | Q3: =IF($P3="NO","NO APLICA",MAX(CEILING(($O3*(1-Configuración!$B$2))/Configuración!$B$3,Configuración!$B$6),Configuración!$B$5)) -> NO APLICA | R3: =IF($Q3="NO APLICA","NO APLICA",$Q3*Configuración!$B$3) -> NO APLICA | S3: =IF($O3<Configuración!$B$8,"NO","SI") -> NO | T3: =IF($S3="NO","NO APLICA",MAX(CEILING(($O3*(1-Configuración!$B$2))/Configuración!$B$4,Configuración!$B$6),Configuración!$B$5)) -> NO APLICA | U3: =IF($T3="NO APLICA","NO APLICA",$T3*Configuración!$B$4) -> NO APLICA | V3: =MAX(CEILING($O3/Configuración!$B$9,Configuración!$B$6),Configuración!$B$5) -> 100 | W3: Activo | X3: 46079
A4: =IF(OR(E4="",F4="",G4=""),"",E4&"-"&F4&"-"&G4&"-"&TEXT(COUNTIFS($E$2:E4,E4,$F$2:F4,F4,$G$2:G4,G4),"000")) -> MOB-SIL-PSL-003 | B4: Mobiliario | C4: Silla | D4: Plástico | E4: =_xlfn.XLOOKUP(B4,Configuración!A:A,Configuración!B:B,"") -> MOB | F4: {=IF($C4="","",_xlfn.XLOOKUP(1,(Configuración!D:D=$B4)*(Configuración!E:E=$C4),Configuración!F:F,""))} -> SIL | G4: =IF($D4="","",_xlfn.XLOOKUP($D4,Configuración!H:H,Configuración!I:I,"")) -> PSL | H4: 4 Sillas Brexia color | I4: 4 Sillas Brexia color | J4: Duna | L4: 2100 | M4: =MAX(CEILING(L4/4,10),100) -> 530 | N4: =M4*4 -> 2120 | O4: 3000 | P4: =IF($O4<Configuración!$B$7,"NO","SI") -> SI | Q4: =IF($P4="NO","NO APLICA",MAX(CEILING(($O4*(1-Configuración!$B$2))/Configuración!$B$3,Configuración!$B$6),Configuración!$B$5)) -> 300 | R4: =IF($Q4="NO APLICA","NO APLICA",$Q4*Configuración!$B$3) -> 2400 | S4: =IF($O4<Configuración!$B$8,"NO","SI") -> SI | T4: =IF($S4="NO","NO APLICA",MAX(CEILING(($O4*(1-Configuración!$B$2))/Configuración!$B$4,Configuración!$B$6),Configuración!$B$5)) -> 200 | U4: =IF($T4="NO APLICA","NO APLICA",$T4*Configuración!$B$4) -> 2400 | V4: =MAX(CEILING($O4/Configuración!$B$9,Configuración!$B$6),Configuración!$B$5) -> 100 | W4: Activo | X4: 46079
A5: =IF(OR(E5="",F5="",G5=""),"",E5&"-"&F5&"-"&G5&"-"&TEXT(COUNTIFS($E$2:E5,E5,$F$2:F5,F5,$G$2:G5,G5),"000")) -> MOB-SIL-PSL-004 | B5: Mobiliario | C5: Silla | D5: Plástico | E5: =_xlfn.XLOOKUP(B5,Configuración!A:A,Configuración!B:B,"") -> MOB | F5: {=IF($C5="","",_xlfn.XLOOKUP(1,(Configuración!D:D=$B5)*(Configuración!E:E=$C5),Configuración!F:F,""))} -> SIL | G5: =IF($D5="","",_xlfn.XLOOKUP($D5,Configuración!H:H,Configuración!I:I,"")) -> PSL | H5: 4 Sillas Pata de elefante color | I5: 4 Sillas Pata de elefante color | J5: Conejo | L5: 2310 | M5: =MAX(CEILING(L5/4,10),100) -> 580 | N5: =M5*4 -> 2320 | O5: 3300 | P5: =IF($O5<Configuración!$B$7,"NO","SI") -> SI | Q5: =IF($P5="NO","NO APLICA",MAX(CEILING(($O5*(1-Configuración!$B$2))/Configuración!$B$3,Configuración!$B$6),Configuración!$B$5)) -> 330 | R5: =IF($Q5="NO APLICA","NO APLICA",$Q5*Configuración!$B$3) -> 2640 | S5: =IF($O5<Configuración!$B$8,"NO","SI") -> SI | T5: =IF($S5="NO","NO APLICA",MAX(CEILING(($O5*(1-Configuración!$B$2))/Configuración!$B$4,Configuración!$B$6),Configuración!$B$5)) -> 220 | U5: =IF($T5="NO APLICA","NO APLICA",$T5*Configuración!$B$4) -> 2640 | V5: =MAX(CEILING($O5/Configuración!$B$9,Configuración!$B$6),Configuración!$B$5) -> 100 | W5: Activo | X5: 46079
A6: =IF(OR(E6="",F6="",G6=""),"",E6&"-"&F6&"-"&G6&"-"&TEXT(COUNTIFS($E$2:E6,E6,$F$2:F6,F6,$G$2:G6,G6),"000")) -> LBL-AIRE-MET-001 | B6: Línea blanca | C6: Aire acondicionado | D6: Metal | E6: =_xlfn.XLOOKUP(B6,Configuración!A:A,Configuración!B:B,"") -> LBL | F6: {=IF($C6="","",_xlfn.XLOOKUP(1,(Configuración!D:D=$B6)*(Configuración!E:E=$C6),Configuración!F:F,""))} -> AIRE | G6: =IF($D6="","",_xlfn.XLOOKUP($D6,Configuración!H:H,Configuración!I:I,"")) -> MET | H6: Aireacondicionado 12000BTU | I6: Aireacondicionado 12000BTU | J6: Hisense | L6: 13950 | M6: =MAX(CEILING(L6/4,10),100) -> 3490 | N6: =M6*4 -> 13960 | O6: 19935 | P6: =IF($O6<Configuración!$B$7,"NO","SI") -> SI | Q6: =IF($P6="NO","NO APLICA",MAX(CEILING(($O6*(1-Configuración!$B$2))/Configuración!$B$3,Configuración!$B$6),Configuración!$B$5)) -> 2000 | R6: =IF($Q6="NO APLICA","NO APLICA",$Q6*Configuración!$B$3) -> 16000 | S6: =IF($O6<Configuración!$B$8,"NO","SI") -> SI | T6: =IF($S6="NO","NO APLICA",MAX(CEILING(($O6*(1-Configuración!$B$2))/Configuración!$B$4,Configuración!$B$6),Configuración!$B$5)) -> 1330 | U6: =IF($T6="NO APLICA","NO APLICA",$T6*Configuración!$B$4) -> 15960 | V6: =MAX(CEILING($O6/Configuración!$B$9,Configuración!$B$6),Configuración!$B$5) -> 390 | W6: Activo | X6: 46079
A7: =IF(OR(E7="",F7="",G7=""),"",E7&"-"&F7&"-"&G7&"-"&TEXT(COUNTIFS($E$2:E7,E7,$F$2:F7,F7,$G$2:G7,G7),"000")) -> MOB-ALA-MAD-001 | B7: Mobiliario | C7: Alacena | D7: Madera | E7: =_xlfn.XLOOKUP(B7,Configuración!A:A,Configuración!B:B,"") -> MOB | F7: {=IF($C7="","",_xlfn.XLOOKUP(1,(Configuración!D:D=$B7)*(Configuración!E:E=$C7),Configuración!F:F,""))} -> ALA | G7: =IF($D7="","",_xlfn.XLOOKUP($D7,Configuración!H:H,Configuración!I:I,"")) -> MAD | H7: Alacena cantinera chica | I7: Alacena cantinera chica | J7: Madera D.C | L7: 7000 | M7: =MAX(CEILING(L7/4,10),100) -> 1750 | N7: =M7*4 -> 7000 | O7: 10000 | P7: =IF($O7<Configuración!$B$7,"NO","SI") -> SI | Q7: =IF($P7="NO","NO APLICA",MAX(CEILING(($O7*(1-Configuración!$B$2))/Configuración!$B$3,Configuración!$B$6),Configuración!$B$5)) -> 1000 | R7: =IF($Q7="NO APLICA","NO APLICA",$Q7*Configuración!$B$3) -> 8000 | S7: =IF($O7<Configuración!$B$8,"NO","SI") -> SI | T7: =IF($S7="NO","NO APLICA",MAX(CEILING(($O7*(1-Configuración!$B$2))/Configuración!$B$4,Configuración!$B$6),Configuración!$B$5)) -> 670 | U7: =IF($T7="NO APLICA","NO APLICA",$T7*Configuración!$B$4) -> 8040 | V7: =MAX(CEILING($O7/Configuración!$B$9,Configuración!$B$6),Configuración!$B$5) -> 200 | W7: Activo | X7: 46079
A8: =IF(OR(E8="",F8="",G8=""),"",E8&"-"&F8&"-"&G8&"-"&TEXT(COUNTIFS($E$2:E8,E8,$F$2:F8,F8,$G$2:G8,G8),"000")) -> MOB-ALA-MAD-002 | B8: Mobiliario | C8: Alacena | D8: Madera | E8: =_xlfn.XLOOKUP(B8,Configuración!A:A,Configuración!B:B,"") -> MOB | F8: {=IF($C8="","",_xlfn.XLOOKUP(1,(Configuración!D:D=$B8)*(Configuración!E:E=$C8),Configuración!F:F,""))} -> ALA | G8: =IF($D8="","",_xlfn.XLOOKUP($D8,Configuración!H:H,Configuración!I:I,"")) -> MAD | H8: Alacena cantinera grande | I8: Alacena cantinera grande | J8: Madera D.C | L8: 8750 | M8: =MAX(CEILING(L8/4,10),100) -> 2190 | N8: =M8*4 -> 8760 | O8: 12500 | P8: =IF($O8<Configuración!$B$7,"NO","SI") -> SI | Q8: =IF($P8="NO","NO APLICA",MAX(CEILING(($O8*(1-Configuración!$B$2))/Configuración!$B$3,Configuración!$B$6),Configuración!$B$5)) -> 1250 | R8: =IF($Q8="NO APLICA","NO APLICA",$Q8*Configuración!$B$3) -> 10000 | S8: =IF($O8<Configuración!$B$8,"NO","SI") -> SI | T8: =IF($S8="NO","NO APLICA",MAX(CEILING(($O8*(1-Configuración!$B$2))/Configuración!$B$4,Configuración!$B$6),Configuración!$B$5)) -> 840 | U8: =IF($T8="NO APLICA","NO APLICA",$T8*Configuración!$B$4) -> 10080 | V8: =MAX(CEILING($O8/Configuración!$B$9,Configuración!$B$6),Configuración!$B$5) -> 250 | W8: Activo | X8: 46079
A9: =IF(OR(E9="",F9="",G9=""),"",E9&"-"&F9&"-"&G9&"-"&TEXT(COUNTIFS($E$2:E9,E9,$F$2:F9,F9,$G$2:G9,G9),"000")) -> MOB-ALA-MAD-003 | B9: Mobiliario | C9: Alacena | D9: Madera | E9: =_xlfn.XLOOKUP(B9,Configuración!A:A,Configuración!B:B,"") -> MOB | F9: {=IF($C9="","",_xlfn.XLOOKUP(1,(Configuración!D:D=$B9)*(Configuración!E:E=$C9),Configuración!F:F,""))} -> ALA | G9: =IF($D9="","",_xlfn.XLOOKUP($D9,Configuración!H:H,Configuración!I:I,"")) -> MAD | H9: Alacena portamicro chica | I9: Alacena portamicro chica | J9: Madera D.C | L9: 4410 | M9: =MAX(CEILING(L9/4,10),100) -> 1110 | N9: =M9*4 -> 4440 | O9: 6300 | P9: =IF($O9<Configuración!$B$7,"NO","SI") -> SI | Q9: =IF($P9="NO","NO APLICA",MAX(CEILING(($O9*(1-Configuración!$B$2))/Configuración!$B$3,Configuración!$B$6),Configuración!$B$5)) -> 630 | R9: =IF($Q9="NO APLICA","NO APLICA",$Q9*Configuración!$B$3) -> 5040 | S9: =IF($O9<Configuración!$B$8,"NO","SI") -> SI | T9: =IF($S9="NO","NO APLICA",MAX(CEILING(($O9*(1-Configuración!$B$2))/Configuración!$B$4,Configuración!$B$6),Configuración!$B$5)) -> 420 | U9: =IF($T9="NO APLICA","NO APLICA",$T9*Configuración!$B$4) -> 5040 | V9: =MAX(CEILING($O9/Configuración!$B$9,Configuración!$B$6),Configuración!$B$5) -> 130 | W9: Activo | X9: 46079
A10: =IF(OR(E10="",F10="",G10=""),"",E10&"-"&F10&"-"&G10&"-"&TEXT(COUNTIFS($E$2:E10,E10,$F$2:F10,F10,$G$2:G10,G10),"000")) -> MOB-ANA-PSL-001 | B10: Mobiliario | C10: Anaquel | D10: Plástico | E10: =_xlfn.XLOOKUP(B10,Configuración!A:A,Configuración!B:B,"") -> MOB | F10: {=IF($C10="","",_xlfn.XLOOKUP(1,(Configuración!D:D=$B10)*(Configuración!E:E=$C10),Configuración!F:F,""))} -> ANA | G10: =IF($D10="","",_xlfn.XLOOKUP($D10,Configuración!H:H,Configuración!I:I,"")) -> PSL | H10: Anaquel de plástico | I10: Anaquel de plástico | J10: Lara | L10: 2310 | M10: =MAX(CEILING(L10/4,10),100) -> 580 | N10: =M10*4 -> 2320 | O10: 3300 | P10: =IF($O10<Configuración!$B$7,"NO","SI") -> SI | Q10: =IF($P10="NO","NO APLICA",MAX(CEILING(($O10*(1-Configuración!$B$2))/Configuración!$B$3,Configuración!$B$6),Configuración!$B$5)) -> 330 | R10: =IF($Q10="NO APLICA","NO APLICA",$Q10*Configuración!$B$3) -> 2640 | S10: =IF($O10<Configuración!$B$8,"NO","SI") -> SI | T10: =IF($S10="NO","NO APLICA",MAX(CEILING(($O10*(1-Configuración!$B$2))/Configuración!$B$4,Configuración!$B$6),Configuración!$B$5)) -> 220 | U10: =IF($T10="NO APLICA","NO APLICA",$T10*Configuración!$B$4) -> 2640 | V10: =MAX(CEILING($O10/Configuración!$B$9,Configuración!$B$6),Configuración!$B$5) -> 100 | W10: Activo | X10: 46079
A11: =IF(OR(E11="",F11="",G11=""),"",E11&"-"&F11&"-"&G11&"-"&TEXT(COUNTIFS($E$2:E11,E11,$F$2:F11,F11,$G$2:G11,G11),"000")) -> MOB-ANA-TUB-001 | B11: Mobiliario | C11: Anaquel | D11: Tubular | E11: =_xlfn.XLOOKUP(B11,Configuración!A:A,Configuración!B:B,"") -> MOB | F11: {=IF($C11="","",_xlfn.XLOOKUP(1,(Configuración!D:D=$B11)*(Configuración!E:E=$C11),Configuración!F:F,""))} -> ANA | G11: =IF($D11="","",_xlfn.XLOOKUP($D11,Configuración!H:H,Configuración!I:I,"")) -> TUB | H11: Anaquel estampado infantil tubular | I11: Anaquel estampado infantil tubular | J11: D.C | L11: 2100 | M11: =MAX(CEILING(L11/4,10),100) -> 530 | N11: =M11*4 -> 2120 | O11: 3000 | P11: =IF($O11<Configuración!$B$7,"NO","SI") -> SI | Q11: =IF($P11="NO","NO APLICA",MAX(CEILING(($O11*(1-Configuración!$B$2))/Configuración!$B$3,Configuración!$B$6),Configuración!$B$5)) -> 300 | R11: =IF($Q11="NO APLICA","NO APLICA",$Q11*Configuración!$B$3) -> 2400 | S11: =IF($O11<Configuración!$B$8,"NO","SI") -> SI | T11: =IF($S11="NO","NO APLICA",MAX(CEILING(($O11*(1-Configuración!$B$2))/Configuración!$B$4,Configuración!$B$6),Configuración!$B$5)) -> 200 | U11: =IF($T11="NO APLICA","NO APLICA",$T11*Configuración!$B$4) -> 2400 | V11: =MAX(CEILING($O11/Configuración!$B$9,Configuración!$B$6),Configuración!$B$5) -> 100 | W11: Activo | X11: 46079
A12: =IF(OR(E12="",F12="",G12=""),"",E12&"-"&F12&"-"&G12&"-"&TEXT(COUNTIFS($E$2:E12,E12,$F$2:F12,F12,$G$2:G12,G12),"000")) -> MOB-ANA-TUB-002 | B12: Mobiliario | C12: Anaquel | D12: Tubular | E12: =_xlfn.XLOOKUP(B12,Configuración!A:A,Configuración!B:B,"") -> MOB | F12: {=IF($C12="","",_xlfn.XLOOKUP(1,(Configuración!D:D=$B12)*(Configuración!E:E=$C12),Configuración!F:F,""))} -> ANA | G12: =IF($D12="","",_xlfn.XLOOKUP($D12,Configuración!H:H,Configuración!I:I,"")) -> TUB | H12: Anaquel tubular | I12: Anaquel tubular | J12: D.C | L12: 1960 | M12: =MAX(CEILING(L12/4,10),100) -> 490 | N12: =M12*4 -> 1960 | O12: 2800 | P12: =IF($O12<Configuración!$B$7,"NO","SI") -> SI | Q12: =IF($P12="NO","NO APLICA",MAX(CEILING(($O12*(1-Configuración!$B$2))/Configuración!$B$3,Configuración!$B$6),Configuración!$B$5)) -> 280 | R12: =IF($Q12="NO APLICA","NO APLICA",$Q12*Configuración!$B$3) -> 2240 | S12: =IF($O12<Configuración!$B$8,"NO","SI") -> NO | T12: =IF($S12="NO","NO APLICA",MAX(CEILING(($O12*(1-Configuración!$B$2))/Configuración!$B$4,Configuración!$B$6),Configuración!$B$5)) -> NO APLICA | U12: =IF($T12="NO APLICA","NO APLICA",$T12*Configuración!$B$4) -> NO APLICA | V12: =MAX(CEILING($O12/Configuración!$B$9,Configuración!$B$6),Configuración!$B$5) -> 100 | W12: Activo | X12: 46079
A13: =IF(OR(E13="",F13="",G13=""),"",E13&"-"&F13&"-"&G13&"-"&TEXT(COUNTIFS($E$2:E13,E13,$F$2:F13,F13,$G$2:G13,G13),"000")) -> COC-ARR-ALU-001 | B13: Cocina | C13: Arrocera | D13: Alumino | E13: =_xlfn.XLOOKUP(B13,Configuración!A:A,Configuración!B:B,"") -> COC | F13: {=IF($C13="","",_xlfn.XLOOKUP(1,(Configuración!D:D=$B13)*(Configuración!E:E=$C13),Configuración!F:F,""))} -> ARR | G13: =IF($D13="","",_xlfn.XLOOKUP($D13,Configuración!H:H,Configuración!I:I,"")) -> ALU | H13: Arrocera 70cm jumbo | I13: Arrocera jumbo | J13: El abuelo | K13: listo | L13: 3500 | M13: =MAX(CEILING(L13/4,10),100) -> 880 | N13: =M13*4 -> 3520 | O13: 5000 | P13: =IF($O13<Configuración!$B$7,"NO","SI") -> SI | Q13: =IF($P13="NO","NO APLICA",MAX(CEILING(($O13*(1-Configuración!$B$2))/Configuración!$B$3,Configuración!$B$6),Configuración!$B$5)) -> 500 | R13: =IF($Q13="NO APLICA","NO APLICA",$Q13*Configuración!$B$3) -> 4000 | S13: =IF($O13<Configuración!$B$8,"NO","SI") -> SI | T13: =IF($S13="NO","NO APLICA",MAX(CEILING(($O13*(1-Configuración!$B$2))/Configuración!$B$4,Configuración!$B$6),Configuración!$B$5)) -> 340 | U13: =IF($T13="NO APLICA","NO APLICA",$T13*Configuración!$B$4) -> 4080 | V13: =MAX(CEILING($O13/Configuración!$B$9,Configuración!$B$6),Configuración!$B$5) -> 100 | W13: Activo | X13: 46079
A14: =IF(OR(E14="",F14="",G14=""),"",E14&"-"&F14&"-"&G14&"-"&TEXT(COUNTIFS($E$2:E14,E14,$F$2:F14,F14,$G$2:G14,G14),"000")) -> COC-ARR-ALU-002 | B14: Cocina | C14: Arrocera | D14: Alumino | E14: =_xlfn.XLOOKUP(B14,Configuración!A:A,Configuración!B:B,"") -> COC | F14: {=IF($C14="","",_xlfn.XLOOKUP(1,(Configuración!D:D=$B14)*(Configuración!E:E=$C14),Configuración!F:F,""))} -> ARR | G14: =IF($D14="","",_xlfn.XLOOKUP($D14,Configuración!H:H,Configuración!I:I,"")) -> ALU | H14: Arrocera tepiaca 3pz | I14: Tepiaca | J14: Maytesa | K14: Listo | L14: 3850 | M14: =MAX(CEILING(L14/4,10),100) -> 970 | N14: =M14*4 -> 3880 | O14: 5500 | P14: =IF($O14<Configuración!$B$7,"NO","SI") -> SI | Q14: =IF($P14="NO","NO APLICA",MAX(CEILING(($O14*(1-Configuración!$B$2))/Configuración!$B$3,Configuración!$B$6),Configuración!$B$5)) -> 550 | R14: =IF($Q14="NO APLICA","NO APLICA",$Q14*Configuración!$B$3) -> 4400 | S14: =IF($O14<Configuración!$B$8,"NO","SI") -> SI | T14: =IF($S14="NO","NO APLICA",MAX(CEILING(($O14*(1-Configuración!$B$2))/Configuración!$B$4,Configuración!$B$6),Configuración!$B$5)) -> 370 | U14: =IF($T14="NO APLICA","NO APLICA",$T14*Configuración!$B$4) -> 4440 | V14: =MAX(CEILING($O14/Configuración!$B$9,Configuración!$B$6),Configuración!$B$5) -> 110 | W14: Activo | X14: 46079
A15: =IF(OR(E15="",F15="",G15=""),"",E15&"-"&F15&"-"&G15&"-"&TEXT(COUNTIFS($E$2:E15,E15,$F$2:F15,F15,$G$2:G15,G15),"000")) -> COC-ARR-ACI-001 | B15: Cocina | C15: Arrocera | D15: Acero inoxidable | E15: =_xlfn.XLOOKUP(B15,Configuración!A:A,Configuración!B:B,"") -> COC | F15: {=IF($C15="","",_xlfn.XLOOKUP(1,(Configuración!D:D=$B15)*(Configuración!E:E=$C15),Configuración!F:F,""))} -> ARR | G15: =IF($D15="","",_xlfn.XLOOKUP($D15,Configuración!H:H,Configuración!I:I,"")) -> ACI | H15: Arrocera Valencia 8pz | I15: Valencia | J15: Acero inoxidable | K15: Listo | L15: 3500 | M15: =MAX(CEILING(L15/4,10),100) -> 880 | N15: =M15*4 -> 3520 | O15: 5000 | P15: =IF($O15<Configuración!$B$7,"NO","SI") -> SI | Q15: =IF($P15="NO","NO APLICA",MAX(CEILING(($O15*(1-Configuración!$B$2))/Configuración!$B$3,Configuración!$B$6),Configuración!$B$5)) -> 500 | R15: =IF($Q15="NO APLICA","NO APLICA",$Q15*Configuración!$B$3) -> 4000 | S15: =IF($O15<Configuración!$B$8,"NO","SI") -> SI | T15: =IF($S15="NO","NO APLICA",MAX(CEILING(($O15*(1-Configuración!$B$2))/Configuración!$B$4,Configuración!$B$6),Configuración!$B$5)) -> 340 | U15: =IF($T15="NO APLICA","NO APLICA",$T15*Configuración!$B$4) -> 4080 | V15: =MAX(CEILING($O15/Configuración!$B$9,Configuración!$B$6),Configuración!$B$5) -> 100 | W15: Activo | X15: 46079
A16: =IF(OR(E16="",F16="",G16=""),"",E16&"-"&F16&"-"&G16&"-"&TEXT(COUNTIFS($E$2:E16,E16,$F$2:F16,F16,$G$2:G16,G16),"000")) -> COC-ARR-ACI-002 | B16: Cocina | C16: Arrocera | D16: Acero inoxidable | E16: =_xlfn.XLOOKUP(B16,Configuración!A:A,Configuración!B:B,"") -> COC | F16: {=IF($C16="","",_xlfn.XLOOKUP(1,(Configuración!D:D=$B16)*(Configuración!E:E=$C16),Configuración!F:F,""))} -> ARR | G16: =IF($D16="","",_xlfn.XLOOKUP($D16,Configuración!H:H,Configuración!I:I,"")) -> ACI | H16: Arrocera Velentina 6pz | I16: Valentina | J16: Acero inoxidable | K16: Listo | L16: 3850 | M16: =MAX(CEILING(L16/4,10),100) -> 970 | N16: =M16*4 -> 3880 | O16: 5500 | P16: =IF($O16<Configuración!$B$7,"NO","SI") -> SI | Q16: =IF($P16="NO","NO APLICA",MAX(CEILING(($O16*(1-Configuración!$B$2))/Configuración!$B$3,Configuración!$B$6),Configuración!$B$5)) -> 550 | R16: =IF($Q16="NO APLICA","NO APLICA",$Q16*Configuración!$B$3) -> 4400 | S16: =IF($O16<Configuración!$B$8,"NO","SI") -> SI | T16: =IF($S16="NO","NO APLICA",MAX(CEILING(($O16*(1-Configuración!$B$2))/Configuración!$B$4,Configuración!$B$6),Configuración!$B$5)) -> 370 | U16: =IF($T16="NO APLICA","NO APLICA",$T16*Configuración!$B$4) -> 4440 | V16: =MAX(CEILING($O16/Configuración!$B$9,Configuración!$B$6),Configuración!$B$5) -> 110 | W16: Activo | X16: 46079
A17: =IF(OR(E17="",F17="",G17=""),"",E17&"-"&F17&"-"&G17&"-"&TEXT(COUNTIFS($E$2:E17,E17,$F$2:F17,F17,$G$2:G17,G17),"000")) -> MOB-BAN-TUB-001 | B17: Mobiliario | C17: Banca | D17: Tubular | E17: =_xlfn.XLOOKUP(B17,Configuración!A:A,Configuración!B:B,"") -> MOB | F17: {=IF($C17="","",_xlfn.XLOOKUP(1,(Configuración!D:D=$B17)*(Configuración!E:E=$C17),Configuración!F:F,""))} -> BAN | G17: =IF($D17="","",_xlfn.XLOOKUP($D17,Configuración!H:H,Configuración!I:I,"")) -> TUB | H17: Banca tapizada tubular | I17: Banca tapizada tubular | J17: D.C | L17: 1960 | M17: =MAX(CEILING(L17/4,10),100) -> 490 | N17: =M17*4 -> 1960 | O17: 2800 | P17: =IF($O17<Configuración!$B$7,"NO","SI") -> SI | Q17: =IF($P17="NO","NO APLICA",MAX(CEILING(($O17*(1-Configuración!$B$2))/Configuración!$B$3,Configuración!$B$6),Configuración!$B$5)) -> 280 | R17: =IF($Q17="NO APLICA","NO APLICA",$Q17*Configuración!$B$3) -> 2240 | S17: =IF($O17<Configuración!$B$8,"NO","SI") -> NO | T17: =IF($S17="NO","NO APLICA",MAX(CEILING(($O17*(1-Configuración!$B$2))/Configuración!$B$4,Configuración!$B$6),Configuración!$B$5)) -> NO APLICA | U17: =IF($T17="NO APLICA","NO APLICA",$T17*Configuración!$B$4) -> NO APLICA | V17: =MAX(CEILING($O17/Configuración!$B$9,Configuración!$B$6),Configuración!$B$5) -> 100 | W17: Activo | X17: 46079
A18: =IF(OR(E18="",F18="",G18=""),"",E18&"-"&F18&"-"&G18&"-"&TEXT(COUNTIFS($E$2:E18,E18,$F$2:F18,F18,$G$2:G18,G18),"000")) -> MOB-BAN-MET-001 | B18: Mobiliario | C18: Banca | D18: Metal | E18: =_xlfn.XLOOKUP(B18,Configuración!A:A,Configuración!B:B,"") -> MOB | F18: {=IF($C18="","",_xlfn.XLOOKUP(1,(Configuración!D:D=$B18)*(Configuración!E:E=$C18),Configuración!F:F,""))} -> BAN | G18: =IF($D18="","",_xlfn.XLOOKUP($D18,Configuración!H:H,Configuración!I:I,"")) -> MET | H18: Banca tejida | I18: Banca tejida | J18: D.C | L18: 2100 | M18: =MAX(CEILING(L18/4,10),100) -> 530 | N18: =M18*4 -> 2120 | O18: 3000 | P18: =IF($O18<Configuración!$B$7,"NO","SI") -> SI | Q18: =IF($P18="NO","NO APLICA",MAX(CEILING(($O18*(1-Configuración!$B$2))/Configuración!$B$3,Configuración!$B$6),Configuración!$B$5)) -> 300 | R18: =IF($Q18="NO APLICA","NO APLICA",$Q18*Configuración!$B$3) -> 2400 | S18: =IF($O18<Configuración!$B$8,"NO","SI") -> SI | T18: =IF($S18="NO","NO APLICA",MAX(CEILING(($O18*(1-Configuración!$B$2))/Configuración!$B$4,Configuración!$B$6),Configuración!$B$5)) -> 200 | U18: =IF($T18="NO APLICA","NO APLICA",$T18*Configuración!$B$4) -> 2400 | V18: =MAX(CEILING($O18/Configuración!$B$9,Configuración!$B$6),Configuración!$B$5) -> 100 | W18: Activo | X18: 46079
A19: =IF(OR(E19="",F19="",G19=""),"",E19&"-"&F19&"-"&G19&"-"&TEXT(COUNTIFS($E$2:E19,E19,$F$2:F19,F19,$G$2:G19,G19),"000")) -> MOB-BCO-TUB-001 | B19: Mobiliario | C19: Banco | D19: Tubular | E19: =_xlfn.XLOOKUP(B19,Configuración!A:A,Configuración!B:B,"") -> MOB | F19: {=IF($C19="","",_xlfn.XLOOKUP(1,(Configuración!D:D=$B19)*(Configuración!E:E=$C19),Configuración!F:F,""))} -> BCO | G19: =IF($D19="","",_xlfn.XLOOKUP($D19,Configuración!H:H,Configuración!I:I,"")) -> TUB | H19: Banco redondo tubular | I19: Banco redondo tubular | J19: D.C | L19: 980 | M19: =MAX(CEILING(L19/4,10),100) -> 250 | N19: =M19*4 -> 1000 | O19: 1400 | P19: =IF($O19<Configuración!$B$7,"NO","SI") -> NO | Q19: =IF($P19="NO","NO APLICA",MAX(CEILING(($O19*(1-Configuración!$B$2))/Configuración!$B$3,Configuración!$B$6),Configuración!$B$5)) -> NO APLICA | R19: =IF($Q19="NO APLICA","NO APLICA",$Q19*Configuración!$B$3) -> NO APLICA | S19: =IF($O19<Configuración!$B$8,"NO","SI") -> NO | T19: =IF($S19="NO","NO APLICA",MAX(CEILING(($O19*(1-Configuración!$B$2))/Configuración!$B$4,Configuración!$B$6),Configuración!$B$5)) -> NO APLICA | U19: =IF($T19="NO APLICA","NO APLICA",$T19*Configuración!$B$4) -> NO APLICA | V19: =MAX(CEILING($O19/Configuración!$B$9,Configuración!$B$6),Configuración!$B$5) -> 100 | W19: Activo | X19: 46079
A20: =IF(OR(E20="",F20="",G20=""),"",E20&"-"&F20&"-"&G20&"-"&TEXT(COUNTIFS($E$2:E20,E20,$F$2:F20,F20,$G$2:G20,G20),"000")) -> COC-BAN-PEL-001 | B20: Cocina | C20: Bandejas | D20: Peltre | E20: =_xlfn.XLOOKUP(B20,Configuración!A:A,Configuración!B:B,"") -> COC | F20: {=IF($C20="","",_xlfn.XLOOKUP(1,(Configuración!D:D=$B20)*(Configuración!E:E=$C20),Configuración!F:F,""))} -> BAN | G20: =IF($D20="","",_xlfn.XLOOKUP($D20,Configuración!H:H,Configuración!I:I,"")) -> PEL | H20: Bandejas de peltre yaretzi 344044 | I20: Bandejas de peltre yaretzi 344044 | J20: Cinsa | K20: listo | L20: 1540 | M20: =MAX(CEILING(L20/4,10),100) -> 390 | N20: =M20*4 -> 1560 | O20: 2200 | P20: =IF($O20<Configuración!$B$7,"NO","SI") -> SI | Q20: =IF($P20="NO","NO APLICA",MAX(CEILING(($O20*(1-Configuración!$B$2))/Configuración!$B$3,Configuración!$B$6),Configuración!$B$5)) -> 220 | R20: =IF($Q20="NO APLICA","NO APLICA",$Q20*Configuración!$B$3) -> 1760 | S20: =IF($O20<Configuración!$B$8,"NO","SI") -> NO | T20: =IF($S20="NO","NO APLICA",MAX(CEILING(($O20*(1-Configuración!$B$2))/Configuración!$B$4,Configuración!$B$6),Configuración!$B$5)) -> NO APLICA | U20: =IF($T20="NO APLICA","NO APLICA",$T20*Configuración!$B$4) -> NO APLICA | V20: =MAX(CEILING($O20/Configuración!$B$9,Configuración!$B$6),Configuración!$B$5) -> 100 | W20: Activo | X20: 46079
A21: =IF(OR(E21="",F21="",G21=""),"",E21&"-"&F21&"-"&G21&"-"&TEXT(COUNTIFS($E$2:E21,E21,$F$2:F21,F21,$G$2:G21,G21),"000")) -> PLA-BAN-PSL-001 | B21: Plásticos | C21: Bañera | D21: Plástico | E21: =_xlfn.XLOOKUP(B21,Configuración!A:A,Configuración!B:B,"") -> PLA | F21: {=IF($C21="","",_xlfn.XLOOKUP(1,(Configuración!D:D=$B21)*(Configuración!E:E=$C21),Configuración!F:F,""))} -> BAN | G21: =IF($D21="","",_xlfn.XLOOKUP($D21,Configuración!H:H,Configuración!I:I,"")) -> PSL | H21: Bañera ovalada 110LTS | I21: Bañera ovalada 110LTS | J21: Placero | L21: 1050 | M21: =MAX(CEILING(L21/4,10),100) -> 270 | N21: =M21*4 -> 1080 | O21: 1500 | P21: =IF($O21<Configuración!$B$7,"NO","SI") -> NO | Q21: =IF($P21="NO","NO APLICA",MAX(CEILING(($O21*(1-Configuración!$B$2))/Configuración!$B$3,Configuración!$B$6),Configuración!$B$5)) -> NO APLICA | R21: =IF($Q21="NO APLICA","NO APLICA",$Q21*Configuración!$B$3) -> NO APLICA | S21: =IF($O21<Configuración!$B$8,"NO","SI") -> NO | T21: =IF($S21="NO","NO APLICA",MAX(CEILING(($O21*(1-Configuración!$B$2))/Configuración!$B$4,Configuración!$B$6),Configuración!$B$5)) -> NO APLICA | U21: =IF($T21="NO APLICA","NO APLICA",$T21*Configuración!$B$4) -> NO APLICA | V21: =MAX(CEILING($O21/Configuración!$B$9,Configuración!$B$6),Configuración!$B$5) -> 100 | W21: Activo | X21: 46079
A22: =IF(OR(E22="",F22="",G22=""),"",E22&"-"&F22&"-"&G22&"-"&TEXT(COUNTIFS($E$2:E22,E22,$F$2:F22,F22,$G$2:G22,G22),"000")) -> PLA-BAN-PSL-002 | B22: Plásticos | C22: Bañera | D22: Plástico | E22: =_xlfn.XLOOKUP(B22,Configuración!A:A,Configuración!B:B,"") -> PLA | F22: {=IF($C22="","",_xlfn.XLOOKUP(1,(Configuración!D:D=$B22)*(Configuración!E:E=$C22),Configuración!F:F,""))} -> BAN | G22: =IF($D22="","",_xlfn.XLOOKUP($D22,Configuración!H:H,Configuración!I:I,"")) -> PSL | H22: Bañera ovalada 210 LTS | I22: Bañera ovalada 210 LTS | J22: Placero | L22: 1330 | M22: =MAX(CEILING(L22/4,10),100) -> 340 | N22: =M22*4 -> 1360 | O22: 1900 | P22: =IF($O22<Configuración!$B$7,"NO","SI") -> NO | Q22: =IF($P22="NO","NO APLICA",MAX(CEILING(($O22*(1-Configuración!$B$2))/Configuración!$B$3,Configuración!$B$6),Configuración!$B$5)) -> NO APLICA | R22: =IF($Q22="NO APLICA","NO APLICA",$Q22*Configuración!$B$3) -> NO APLICA | S22: =IF($O22<Configuración!$B$8,"NO","SI") -> NO | T22: =IF($S22="NO","NO APLICA",MAX(CEILING(($O22*(1-Configuración!$B$2))/Configuración!$B$4,Configuración!$B$6),Configuración!$B$5)) -> NO APLICA | U22: =IF($T22="NO APLICA","NO APLICA",$T22*Configuración!$B$4) -> NO APLICA | V22: =MAX(CEILING($O22/Configuración!$B$9,Configuración!$B$6),Configuración!$B$5) -> 100 | W22: Activo | X22: 46079
A23: =IF(OR(E23="",F23="",G23=""),"",E23&"-"&F23&"-"&G23&"-"&TEXT(COUNTIFS($E$2:E23,E23,$F$2:F23,F23,$G$2:G23,G23),"000")) -> PLA-BAN-PSL-003 | B23: Plásticos | C23: Bañera | D23: Plástico | E23: =_xlfn.XLOOKUP(B23,Configuración!A:A,Configuración!B:B,"") -> PLA | F23: {=IF($C23="","",_xlfn.XLOOKUP(1,(Configuración!D:D=$B23)*(Configuración!E:E=$C23),Configuración!F:F,""))} -> BAN | G23: =IF($D23="","",_xlfn.XLOOKUP($D23,Configuración!H:H,Configuración!I:I,"")) -> PSL | H23: Bañera ovalada 310LTS | I23: Bañera ovalada 310LTS | J23: Placero | L23: 1855 | M23: =MAX(CEILING(L23/4,10),100) -> 470 | N23: =M23*4 -> 1880 | O23: 2650 | P23: =IF($O23<Configuración!$B$7,"NO","SI") -> SI | Q23: =IF($P23="NO","NO APLICA",MAX(CEILING(($O23*(1-Configuración!$B$2))/Configuración!$B$3,Configuración!$B$6),Configuración!$B$5)) -> 270 | R23: =IF($Q23="NO APLICA","NO APLICA",$Q23*Configuración!$B$3) -> 2160 | S23: =IF($O23<Configuración!$B$8,"NO","SI") -> NO | T23: =IF($S23="NO","NO APLICA",MAX(CEILING(($O23*(1-Configuración!$B$2))/Configuración!$B$4,Configuración!$B$6),Configuración!$B$5)) -> NO APLICA | U23: =IF($T23="NO APLICA","NO APLICA",$T23*Configuración!$B$4) -> NO APLICA | V23: =MAX(CEILING($O23/Configuración!$B$9,Configuración!$B$6),Configuración!$B$5) -> 100 | W23: Activo | X23: 46079
A24: =IF(OR(E24="",F24="",G24=""),"",E24&"-"&F24&"-"&G24&"-"&TEXT(COUNTIFS($E$2:E24,E24,$F$2:F24,F24,$G$2:G24,G24),"000")) -> PLA-BAN-PSL-004 | B24: Plásticos | C24: Bañera | D24: Plástico | E24: =_xlfn.XLOOKUP(B24,Configuración!A:A,Configuración!B:B,"") -> PLA | F24: {=IF($C24="","",_xlfn.XLOOKUP(1,(Configuración!D:D=$B24)*(Configuración!E:E=$C24),Configuración!F:F,""))} -> BAN | G24: =IF($D24="","",_xlfn.XLOOKUP($D24,Configuración!H:H,Configuración!I:I,"")) -> PSL | H24: Bañera ovalada 380LTS | I24: Bañera ovalada 380LTS | J24: Placero | L24: 2450 | M24: =MAX(CEILING(L24/4,10),100) -> 620 | N24: =M24*4 -> 2480 | O24: 3500 | P24: =IF($O24<Configuración!$B$7,"NO","SI") -> SI | Q24: =IF($P24="NO","NO APLICA",MAX(CEILING(($O24*(1-Configuración!$B$2))/Configuración!$B$3,Configuración!$B$6),Configuración!$B$5)) -> 350 | R24: =IF($Q24="NO APLICA","NO APLICA",$Q24*Configuración!$B$3) -> 2800 | S24: =IF($O24<Configuración!$B$8,"NO","SI") -> SI | T24: =IF($S24="NO","NO APLICA",MAX(CEILING(($O24*(1-Configuración!$B$2))/Configuración!$B$4,Configuración!$B$6),Configuración!$B$5)) -> 240 | U24: =IF($T24="NO APLICA","NO APLICA",$T24*Configuración!$B$4) -> 2880 | V24: =MAX(CEILING($O24/Configuración!$B$9,Configuración!$B$6),Configuración!$B$5) -> 100 | W24: Activo | X24: 46079
A25: =IF(OR(E25="",F25="",G25=""),"",E25&"-"&F25&"-"&G25&"-"&TEXT(COUNTIFS($E$2:E25,E25,$F$2:F25,F25,$G$2:G25,G25),"000")) -> PLA-BAN-PSL-005 | B25: Plásticos | C25: Bañera | D25: Plástico | E25: =_xlfn.XLOOKUP(B25,Configuración!A:A,Configuración!B:B,"") -> PLA | F25: {=IF($C25="","",_xlfn.XLOOKUP(1,(Configuración!D:D=$B25)*(Configuración!E:E=$C25),Configuración!F:F,""))} -> BAN | G25: =IF($D25="","",_xlfn.XLOOKUP($D25,Configuración!H:H,Configuración!I:I,"")) -> PSL | H25: Bañera ovalada 400LTS | I25: Bañera ovalada 400LTS | J25: Placero | L25: 2660 | M25: =MAX(CEILING(L25/4,10),100) -> 670 | N25: =M25*4 -> 2680 | O25: 3700 | P25: =IF($O25<Configuración!$B$7,"NO","SI") -> SI | Q25: =IF($P25="NO","NO APLICA",MAX(CEILING(($O25*(1-Configuración!$B$2))/Configuración!$B$3,Configuración!$B$6),Configuración!$B$5)) -> 370 | R25: =IF($Q25="NO APLICA","NO APLICA",$Q25*Configuración!$B$3) -> 2960 | S25: =IF($O25<Configuración!$B$8,"NO","SI") -> SI | T25: =IF($S25="NO","NO APLICA",MAX(CEILING(($O25*(1-Configuración!$B$2))/Configuración!$B$4,Configuración!$B$6),Configuración!$B$5)) -> 250 | U25: =IF($T25="NO APLICA","NO APLICA",$T25*Configuración!$B$4) -> 3000 | V25: =MAX(CEILING($O25/Configuración!$B$9,Configuración!$B$6),Configuración!$B$5) -> 100 | W25: Activo | X25: 46079
A26: =IF(OR(E26="",F26="",G26=""),"",E26&"-"&F26&"-"&G26&"-"&TEXT(COUNTIFS($E$2:E26,E26,$F$2:F26,F26,$G$2:G26,G26),"000")) -> PLA-BAN-PSL-006 | B26: Plásticos | C26: Bañera | D26: Plástico | E26: =_xlfn.XLOOKUP(B26,Configuración!A:A,Configuración!B:B,"") -> PLA | F26: {=IF($C26="","",_xlfn.XLOOKUP(1,(Configuración!D:D=$B26)*(Configuración!E:E=$C26),Configuración!F:F,""))} -> BAN | G26: =IF($D26="","",_xlfn.XLOOKUP($D26,Configuración!H:H,Configuración!I:I,"")) -> PSL | H26: Bañera ovalada 650LTS | I26: Bañera ovalada 650LTS | J26: Placero | L26: 3950 | M26: =MAX(CEILING(L26/4,10),100) -> 990 | N26: =M26*4 -> 3960 | O26: 6000 | P26: =IF($O26<Configuración!$B$7,"NO","SI") -> SI | Q26: =IF($P26="NO","NO APLICA",MAX(CEILING(($O26*(1-Configuración!$B$2))/Configuración!$B$3,Configuración!$B$6),Configuración!$B$5)) -> 600 | R26: =IF($Q26="NO APLICA","NO APLICA",$Q26*Configuración!$B$3) -> 4800 | S26: =IF($O26<Configuración!$B$8,"NO","SI") -> SI | T26: =IF($S26="NO","NO APLICA",MAX(CEILING(($O26*(1-Configuración!$B$2))/Configuración!$B$4,Configuración!$B$6),Configuración!$B$5)) -> 400 | U26: =IF($T26="NO APLICA","NO APLICA",$T26*Configuración!$B$4) -> 4800 | V26: =MAX(CEILING($O26/Configuración!$B$9,Configuración!$B$6),Configuración!$B$5) -> 120 | W26: Activo | X26: 46079
A27: =IF(OR(E27="",F27="",G27=""),"",E27&"-"&F27&"-"&G27&"-"&TEXT(COUNTIFS($E$2:E27,E27,$F$2:F27,F27,$G$2:G27,G27),"000")) -> PLA-BAN-PSL-007 | B27: Plásticos | C27: Bañera | D27: Plástico | E27: =_xlfn.XLOOKUP(B27,Configuración!A:A,Configuración!B:B,"") -> PLA | F27: {=IF($C27="","",_xlfn.XLOOKUP(1,(Configuración!D:D=$B27)*(Configuración!E:E=$C27),Configuración!F:F,""))} -> BAN | G27: =IF($D27="","",_xlfn.XLOOKUP($D27,Configuración!H:H,Configuración!I:I,"")) -> PSL | H27: Bañera ovalada 700LTS | I27: Bañera ovalada 700LTS | J27: Placero | L27: 4340 | M27: =MAX(CEILING(L27/4,10),100) -> 1090 | N27: =M27*4 -> 4360 | O27: 6600 | P27: =IF($O27<Configuración!$B$7,"NO","SI") -> SI | Q27: =IF($P27="NO","NO APLICA",MAX(CEILING(($O27*(1-Configuración!$B$2))/Configuración!$B$3,Configuración!$B$6),Configuración!$B$5)) -> 660 | R27: =IF($Q27="NO APLICA","NO APLICA",$Q27*Configuración!$B$3) -> 5280 | S27: =IF($O27<Configuración!$B$8,"NO","SI") -> SI | T27: =IF($S27="NO","NO APLICA",MAX(CEILING(($O27*(1-Configuración!$B$2))/Configuración!$B$4,Configuración!$B$6),Configuración!$B$5)) -> 440 | U27: =IF($T27="NO APLICA","NO APLICA",$T27*Configuración!$B$4) -> 5280 | V27: =MAX(CEILING($O27/Configuración!$B$9,Configuración!$B$6),Configuración!$B$5) -> 130 | W27: Activo | X27: 46079
A28: =IF(OR(E28="",F28="",G28=""),"",E28&"-"&F28&"-"&G28&"-"&TEXT(COUNTIFS($E$2:E28,E28,$F$2:F28,F28,$G$2:G28,G28),"000")) -> PLA-BAN-PSL-008 | B28: Plásticos | C28: Bañera | D28: Plástico | E28: =_xlfn.XLOOKUP(B28,Configuración!A:A,Configuración!B:B,"") -> PLA | F28: {=IF($C28="","",_xlfn.XLOOKUP(1,(Configuración!D:D=$B28)*(Configuración!E:E=$C28),Configuración!F:F,""))} -> BAN | G28: =IF($D28="","",_xlfn.XLOOKUP($D28,Configuración!H:H,Configuración!I:I,"")) -> PSL | H28: Bañera ovalada 900LTS | I28: Bañera ovalada 900LTS | J28: Placero | L28: 5110 | M28: =MAX(CEILING(L28/4,10),100) -> 1280 | N28: =M28*4 -> 5120 | O28: 7400 | P28: =IF($O28<Configuración!$B$7,"NO","SI") -> SI | Q28: =IF($P28="NO","NO APLICA",MAX(CEILING(($O28*(1-Configuración!$B$2))/Configuración!$B$3,Configuración!$B$6),Configuración!$B$5)) -> 740 | R28: =IF($Q28="NO APLICA","NO APLICA",$Q28*Configuración!$B$3) -> 5920 | S28: =IF($O28<Configuración!$B$8,"NO","SI") -> SI | T28: =IF($S28="NO","NO APLICA",MAX(CEILING(($O28*(1-Configuración!$B$2))/Configuración!$B$4,Configuración!$B$6),Configuración!$B$5)) -> 500 | U28: =IF($T28="NO APLICA","NO APLICA",$T28*Configuración!$B$4) -> 6000 | V28: =MAX(CEILING($O28/Configuración!$B$9,Configuración!$B$6),Configuración!$B$5) -> 150 | W28: Activo | X28: 46079
A29: =IF(OR(E29="",F29="",G29=""),"",E29&"-"&F29&"-"&G29&"-"&TEXT(COUNTIFS($E$2:E29,E29,$F$2:F29,F29,$G$2:G29,G29),"000")) -> COC-BAT-ALU-001 | B29: Cocina | C29: Batería | D29: Alumino | E29: =_xlfn.XLOOKUP(B29,Configuración!A:A,Configuración!B:B,"") -> COC | F29: {=IF($C29="","",_xlfn.XLOOKUP(1,(Configuración!D:D=$B29)*(Configuración!E:E=$C29),Configuración!F:F,""))} -> BAT | G29: =IF($D29="","",_xlfn.XLOOKUP($D29,Configuración!H:H,Configuración!I:I,"")) -> ALU | H29: Batería acayuqueña 9pz | I29: Acayuqueña | J29: El abuelo | K29: Listo | L29: 2100 | M29: =MAX(CEILING(L29/4,10),100) -> 530 | N29: =M29*4 -> 2120 | O29: 3000 | P29: =IF($O29<Configuración!$B$7,"NO","SI") -> SI | Q29: =IF($P29="NO","NO APLICA",MAX(CEILING(($O29*(1-Configuración!$B$2))/Configuración!$B$3,Configuración!$B$6),Configuración!$B$5)) -> 300 | R29: =IF($Q29="NO APLICA","NO APLICA",$Q29*Configuración!$B$3) -> 2400 | S29: =IF($O29<Configuración!$B$8,"NO","SI") -> SI | T29: =IF($S29="NO","NO APLICA",MAX(CEILING(($O29*(1-Configuración!$B$2))/Configuración!$B$4,Configuración!$B$6),Configuración!$B$5)) -> 200 | U29: =IF($T29="NO APLICA","NO APLICA",$T29*Configuración!$B$4) -> 2400 | V29: =MAX(CEILING($O29/Configuración!$B$9,Configuración!$B$6),Configuración!$B$5) -> 100 | W29: Activo | X29: 46079
A30: =IF(OR(E30="",F30="",G30=""),"",E30&"-"&F30&"-"&G30&"-"&TEXT(COUNTIFS($E$2:E30,E30,$F$2:F30,F30,$G$2:G30,G30),"000")) -> COC-BAT-ALU-002 | B30: Cocina | C30: Batería | D30: Alumino | E30: =_xlfn.XLOOKUP(B30,Configuración!A:A,Configuración!B:B,"") -> COC | F30: {=IF($C30="","",_xlfn.XLOOKUP(1,(Configuración!D:D=$B30)*(Configuración!E:E=$C30),Configuración!F:F,""))} -> BAT | G30: =IF($D30="","",_xlfn.XLOOKUP($D30,Configuración!H:H,Configuración!I:I,"")) -> ALU | H30: Batería córdoba 14pz | I30: Córdoba | J30: El abuelo | K30: listo | L30: 2520 | M30: =MAX(CEILING(L30/4,10),100) -> 630 | N30: =M30*4 -> 2520 | O30: 4000 | P30: =IF($O30<Configuración!$B$7,"NO","SI") -> SI | Q30: =IF($P30="NO","NO APLICA",MAX(CEILING(($O30*(1-Configuración!$B$2))/Configuración!$B$3,Configuración!$B$6),Configuración!$B$5)) -> 400 | R30: =IF($Q30="NO APLICA","NO APLICA",$Q30*Configuración!$B$3) -> 3200 | S30: =IF($O30<Configuración!$B$8,"NO","SI") -> SI | T30: =IF($S30="NO","NO APLICA",MAX(CEILING(($O30*(1-Configuración!$B$2))/Configuración!$B$4,Configuración!$B$6),Configuración!$B$5)) -> 270 | U30: =IF($T30="NO APLICA","NO APLICA",$T30*Configuración!$B$4) -> 3240 | V30: =MAX(CEILING($O30/Configuración!$B$9,Configuración!$B$6),Configuración!$B$5) -> 100 | W30: Activo | X30: 46079
A31: =IF(OR(E31="",F31="",G31=""),"",E31&"-"&F31&"-"&G31&"-"&TEXT(COUNTIFS($E$2:E31,E31,$F$2:F31,F31,$G$2:G31,G31),"000")) -> COC-BAT-PEL-001 | B31: Cocina | C31: Batería | D31: Peltre | E31: =_xlfn.XLOOKUP(B31,Configuración!A:A,Configuración!B:B,"") -> COC | F31: {=IF($C31="","",_xlfn.XLOOKUP(1,(Configuración!D:D=$B31)*(Configuración!E:E=$C31),Configuración!F:F,""))} -> BAT | G31: =IF($D31="","",_xlfn.XLOOKUP($D31,Configuración!H:H,Configuración!I:I,"")) -> PEL | H31: Batería de peltre chiapaneca 10pz | I31: Chiapaneca | J31: Cinsa | K31: listo | L31: 2520 | M31: =MAX(CEILING(L31/4,10),100) -> 630 | N31: =M31*4 -> 2520 | O31: 3600 | P31: =IF($O31<Configuración!$B$7,"NO","SI") -> SI | Q31: =IF($P31="NO","NO APLICA",MAX(CEILING(($O31*(1-Configuración!$B$2))/Configuración!$B$3,Configuración!$B$6),Configuración!$B$5)) -> 360 | R31: =IF($Q31="NO APLICA","NO APLICA",$Q31*Configuración!$B$3) -> 2880 | S31: =IF($O31<Configuración!$B$8,"NO","SI") -> SI | T31: =IF($S31="NO","NO APLICA",MAX(CEILING(($O31*(1-Configuración!$B$2))/Configuración!$B$4,Configuración!$B$6),Configuración!$B$5)) -> 240 | U31: =IF($T31="NO APLICA","NO APLICA",$T31*Configuración!$B$4) -> 2880 | V31: =MAX(CEILING($O31/Configuración!$B$9,Configuración!$B$6),Configuración!$B$5) -> 100 | W31: Activo | X31: 46079
A32: =IF(OR(E32="",F32="",G32=""),"",E32&"-"&F32&"-"&G32&"-"&TEXT(COUNTIFS($E$2:E32,E32,$F$2:F32,F32,$G$2:G32,G32),"000")) -> COC-BAT-PEL-002 | B32: Cocina | C32: Batería | D32: Peltre | E32: =_xlfn.XLOOKUP(B32,Configuración!A:A,Configuración!B:B,"") -> COC | F32: {=IF($C32="","",_xlfn.XLOOKUP(1,(Configuración!D:D=$B32)*(Configuración!E:E=$C32),Configuración!F:F,""))} -> BAT | G32: =IF($D32="","",_xlfn.XLOOKUP($D32,Configuración!H:H,Configuración!I:I,"")) -> PEL | H32: Batería de peltre duramax 13pz negro | I32: Duramax | J32: Cinsa | K32: listo | L32: 3500 | M32: =MAX(CEILING(L32/4,10),100) -> 880 | N32: =M32*4 -> 3520 | O32: 5000 | P32: =IF($O32<Configuración!$B$7,"NO","SI") -> SI | Q32: =IF($P32="NO","NO APLICA",MAX(CEILING(($O32*(1-Configuración!$B$2))/Configuración!$B$3,Configuración!$B$6),Configuración!$B$5)) -> 500 | R32: =IF($Q32="NO APLICA","NO APLICA",$Q32*Configuración!$B$3) -> 4000 | S32: =IF($O32<Configuración!$B$8,"NO","SI") -> SI | T32: =IF($S32="NO","NO APLICA",MAX(CEILING(($O32*(1-Configuración!$B$2))/Configuración!$B$4,Configuración!$B$6),Configuración!$B$5)) -> 340 | U32: =IF($T32="NO APLICA","NO APLICA",$T32*Configuración!$B$4) -> 4080 | V32: =MAX(CEILING($O32/Configuración!$B$9,Configuración!$B$6),Configuración!$B$5) -> 100 | W32: Activo | X32: 46079
A33: =IF(OR(E33="",F33="",G33=""),"",E33&"-"&F33&"-"&G33&"-"&TEXT(COUNTIFS($E$2:E33,E33,$F$2:F33,F33,$G$2:G33,G33),"000")) -> COC-BAT-PEL-003 | B33: Cocina | C33: Batería | D33: Peltre | E33: =_xlfn.XLOOKUP(B33,Configuración!A:A,Configuración!B:B,"") -> COC | F33: {=IF($C33="","",_xlfn.XLOOKUP(1,(Configuración!D:D=$B33)*(Configuración!E:E=$C33),Configuración!F:F,""))} -> BAT | G33: =IF($D33="","",_xlfn.XLOOKUP($D33,Configuración!H:H,Configuración!I:I,"")) -> PEL | H33: Batería de peltre Esperanza verde 10pz | I33: Esperanza | J33: Cinsa | K33: listo | L33: 2100 | M33: =MAX(CEILING(L33/4,10),100) -> 530 | N33: =M33*4 -> 2120 | O33: 3000 | P33: =IF($O33<Configuración!$B$7,"NO","SI") -> SI | Q33: =IF($P33="NO","NO APLICA",MAX(CEILING(($O33*(1-Configuración!$B$2))/Configuración!$B$3,Configuración!$B$6),Configuración!$B$5)) -> 300 | R33: =IF($Q33="NO APLICA","NO APLICA",$Q33*Configuración!$B$3) -> 2400 | S33: =IF($O33<Configuración!$B$8,"NO","SI") -> SI | T33: =IF($S33="NO","NO APLICA",MAX(CEILING(($O33*(1-Configuración!$B$2))/Configuración!$B$4,Configuración!$B$6),Configuración!$B$5)) -> 200 | U33: =IF($T33="NO APLICA","NO APLICA",$T33*Configuración!$B$4) -> 2400 | V33: =MAX(CEILING($O33/Configuración!$B$9,Configuración!$B$6),Configuración!$B$5) -> 100 | W33: Activo | X33: 46079
A34: =IF(OR(E34="",F34="",G34=""),"",E34&"-"&F34&"-"&G34&"-"&TEXT(COUNTIFS($E$2:E34,E34,$F$2:F34,F34,$G$2:G34,G34),"000")) -> COC-BAT-PEL-004 | B34: Cocina | C34: Batería | D34: Peltre | E34: =_xlfn.XLOOKUP(B34,Configuración!A:A,Configuración!B:B,"") -> COC | F34: {=IF($C34="","",_xlfn.XLOOKUP(1,(Configuración!D:D=$B34)*(Configuración!E:E=$C34),Configuración!F:F,""))} -> BAT | G34: =IF($D34="","",_xlfn.XLOOKUP($D34,Configuración!H:H,Configuración!I:I,"")) -> PEL | H34: Batería de peltre Fernanda verde 10pz | I34: Fernanda | J34: Cinsa | K34: listo | L34: 2100 | M34: =MAX(CEILING(L34/4,10),100) -> 530 | N34: =M34*4 -> 2120 | O34: 3000 | P34: =IF($O34<Configuración!$B$7,"NO","SI") -> SI | Q34: =IF($P34="NO","NO APLICA",MAX(CEILING(($O34*(1-Configuración!$B$2))/Configuración!$B$3,Configuración!$B$6),Configuración!$B$5)) -> 300 | R34: =IF($Q34="NO APLICA","NO APLICA",$Q34*Configuración!$B$3) -> 2400 | S34: =IF($O34<Configuración!$B$8,"NO","SI") -> SI | T34: =IF($S34="NO","NO APLICA",MAX(CEILING(($O34*(1-Configuración!$B$2))/Configuración!$B$4,Configuración!$B$6),Configuración!$B$5)) -> 200 | U34: =IF($T34="NO APLICA","NO APLICA",$T34*Configuración!$B$4) -> 2400 | V34: =MAX(CEILING($O34/Configuración!$B$9,Configuración!$B$6),Configuración!$B$5) -> 100 | W34: Activo | X34: 46079
A35: =IF(OR(E35="",F35="",G35=""),"",E35&"-"&F35&"-"&G35&"-"&TEXT(COUNTIFS($E$2:E35,E35,$F$2:F35,F35,$G$2:G35,G35),"000")) -> COC-BAT-PEL-005 | B35: Cocina | C35: Batería | D35: Peltre | E35: =_xlfn.XLOOKUP(B35,Configuración!A:A,Configuración!B:B,"") -> COC | F35: {=IF($C35="","",_xlfn.XLOOKUP(1,(Configuración!D:D=$B35)*(Configuración!E:E=$C35),Configuración!F:F,""))} -> BAT | G35: =IF($D35="","",_xlfn.XLOOKUP($D35,Configuración!H:H,Configuración!I:I,"")) -> PEL | H35: Batería de peltre pontevedra 11pz | I35: Pontevedra | J35: Cinsa | K35: listo | L35: 3500 | M35: =MAX(CEILING(L35/4,10),100) -> 880 | N35: =M35*4 -> 3520 | O35: 4995 | P35: =IF($O35<Configuración!$B$7,"NO","SI") -> SI | Q35: =IF($P35="NO","NO APLICA",MAX(CEILING(($O35*(1-Configuración!$B$2))/Configuración!$B$3,Configuración!$B$6),Configuración!$B$5)) -> 500 | R35: =IF($Q35="NO APLICA","NO APLICA",$Q35*Configuración!$B$3) -> 4000 | S35: =IF($O35<Configuración!$B$8,"NO","SI") -> SI | T35: =IF($S35="NO","NO APLICA",MAX(CEILING(($O35*(1-Configuración!$B$2))/Configuración!$B$4,Configuración!$B$6),Configuración!$B$5)) -> 340 | U35: =IF($T35="NO APLICA","NO APLICA",$T35*Configuración!$B$4) -> 4080 | V35: =MAX(CEILING($O35/Configuración!$B$9,Configuración!$B$6),Configuración!$B$5) -> 100 | W35: Activo | X35: 46079
A36: =IF(OR(E36="",F36="",G36=""),"",E36&"-"&F36&"-"&G36&"-"&TEXT(COUNTIFS($E$2:E36,E36,$F$2:F36,F36,$G$2:G36,G36),"000")) -> COC-BAT-PEL-006 | B36: Cocina | C36: Batería | D36: Peltre | E36: =_xlfn.XLOOKUP(B36,Configuración!A:A,Configuración!B:B,"") -> COC | F36: {=IF($C36="","",_xlfn.XLOOKUP(1,(Configuración!D:D=$B36)*(Configuración!E:E=$C36),Configuración!F:F,""))} -> BAT | G36: =IF($D36="","",_xlfn.XLOOKUP($D36,Configuración!H:H,Configuración!I:I,"")) -> PEL | H36: Batería de peltre Tuxtla 12pz | I36: Tuxtla | J36: Cinsa | K36: listo | L36: 2800 | M36: =MAX(CEILING(L36/4,10),100) -> 700 | N36: =M36*4 -> 2800 | O36: 4000 | P36: =IF($O36<Configuración!$B$7,"NO","SI") -> SI | Q36: =IF($P36="NO","NO APLICA",MAX(CEILING(($O36*(1-Configuración!$B$2))/Configuración!$B$3,Configuración!$B$6),Configuración!$B$5)) -> 400 | R36: =IF($Q36="NO APLICA","NO APLICA",$Q36*Configuración!$B$3) -> 3200 | S36: =IF($O36<Configuración!$B$8,"NO","SI") -> SI | T36: =IF($S36="NO","NO APLICA",MAX(CEILING(($O36*(1-Configuración!$B$2))/Configuración!$B$4,Configuración!$B$6),Configuración!$B$5)) -> 270 | U36: =IF($T36="NO APLICA","NO APLICA",$T36*Configuración!$B$4) -> 3240 | V36: =MAX(CEILING($O36/Configuración!$B$9,Configuración!$B$6),Configuración!$B$5) -> 100 | W36: Activo | X36: 46079
A37: =IF(OR(E37="",F37="",G37=""),"",E37&"-"&F37&"-"&G37&"-"&TEXT(COUNTIFS($E$2:E37,E37,$F$2:F37,F37,$G$2:G37,G37),"000")) -> COC-BAT-ALUT-001 | B37: Cocina | C37: Batería | D37: Alumino y Teflon | E37: =_xlfn.XLOOKUP(B37,Configuración!A:A,Configuración!B:B,"") -> COC | F37: {=IF($C37="","",_xlfn.XLOOKUP(1,(Configuración!D:D=$B37)*(Configuración!E:E=$C37),Configuración!F:F,""))} -> BAT | G37: =IF($D37="","",_xlfn.XLOOKUP($D37,Configuración!H:H,Configuración!I:I,"")) -> ALUT | H37: Batería de teflón Habana naranja | I37: Bateria Habana | J37: Cinsa | K37: listo | L37: 2800 | M37: =MAX(CEILING(L37/4,10),100) -> 700 | N37: =M37*4 -> 2800 | O37: 4000 | P37: =IF($O37<Configuración!$B$7,"NO","SI") -> SI | Q37: =IF($P37="NO","NO APLICA",MAX(CEILING(($O37*(1-Configuración!$B$2))/Configuración!$B$3,Configuración!$B$6),Configuración!$B$5)) -> 400 | R37: =IF($Q37="NO APLICA","NO APLICA",$Q37*Configuración!$B$3) -> 3200 | S37: =IF($O37<Configuración!$B$8,"NO","SI") -> SI | T37: =IF($S37="NO","NO APLICA",MAX(CEILING(($O37*(1-Configuración!$B$2))/Configuración!$B$4,Configuración!$B$6),Configuración!$B$5)) -> 270 | U37: =IF($T37="NO APLICA","NO APLICA",$T37*Configuración!$B$4) -> 3240 | V37: =MAX(CEILING($O37/Configuración!$B$9,Configuración!$B$6),Configuración!$B$5) -> 100 | W37: Activo | X37: 46079
A38: =IF(OR(E38="",F38="",G38=""),"",E38&"-"&F38&"-"&G38&"-"&TEXT(COUNTIFS($E$2:E38,E38,$F$2:F38,F38,$G$2:G38,G38),"000")) -> COC-BAT-ALUT-002 | B38: Cocina | C38: Batería | D38: Alumino y Teflon | E38: =_xlfn.XLOOKUP(B38,Configuración!A:A,Configuración!B:B,"") -> COC | F38: {=IF($C38="","",_xlfn.XLOOKUP(1,(Configuración!D:D=$B38)*(Configuración!E:E=$C38),Configuración!F:F,""))} -> BAT | G38: =IF($D38="","",_xlfn.XLOOKUP($D38,Configuración!H:H,Configuración!I:I,"")) -> ALUT | H38: Batería de teflón negro 19pz | I38: Bateria Eko | J38: Eko | K38: listo | L38: 2940 | M38: =MAX(CEILING(L38/4,10),100) -> 740 | N38: =M38*4 -> 2960 | O38: 4200 | P38: =IF($O38<Configuración!$B$7,"NO","SI") -> SI | Q38: =IF($P38="NO","NO APLICA",MAX(CEILING(($O38*(1-Configuración!$B$2))/Configuración!$B$3,Configuración!$B$6),Configuración!$B$5)) -> 420 | R38: =IF($Q38="NO APLICA","NO APLICA",$Q38*Configuración!$B$3) -> 3360 | S38: =IF($O38<Configuración!$B$8,"NO","SI") -> SI | T38: =IF($S38="NO","NO APLICA",MAX(CEILING(($O38*(1-Configuración!$B$2))/Configuración!$B$4,Configuración!$B$6),Configuración!$B$5)) -> 280 | U38: =IF($T38="NO APLICA","NO APLICA",$T38*Configuración!$B$4) -> 3360 | V38: =MAX(CEILING($O38/Configuración!$B$9,Configuración!$B$6),Configuración!$B$5) -> 100 | W38: Activo | X38: 46079
A39: =IF(OR(E39="",F39="",G39=""),"",E39&"-"&F39&"-"&G39&"-"&TEXT(COUNTIFS($E$2:E39,E39,$F$2:F39,F39,$G$2:G39,G39),"000")) -> COC-BAT-ALUT-003 | B39: Cocina | C39: Batería | D39: Alumino y Teflon | E39: =_xlfn.XLOOKUP(B39,Configuración!A:A,Configuración!B:B,"") -> COC | F39: {=IF($C39="","",_xlfn.XLOOKUP(1,(Configuración!D:D=$B39)*(Configuración!E:E=$C39),Configuración!F:F,""))} -> BAT | G39: =IF($D39="","",_xlfn.XLOOKUP($D39,Configuración!H:H,Configuración!I:I,"")) -> ALUT | H39: Batería de teflon tobago | I39: Tobago | J39: Cinsa | K39: listo | L39: 4000 | M39: =MAX(CEILING(L39/4,10),100) -> 1000 | N39: =M39*4 -> 4000 | O39: 5700 | P39: =IF($O39<Configuración!$B$7,"NO","SI") -> SI | Q39: =IF($P39="NO","NO APLICA",MAX(CEILING(($O39*(1-Configuración!$B$2))/Configuración!$B$3,Configuración!$B$6),Configuración!$B$5)) -> 570 | R39: =IF($Q39="NO APLICA","NO APLICA",$Q39*Configuración!$B$3) -> 4560 | S39: =IF($O39<Configuración!$B$8,"NO","SI") -> SI | T39: =IF($S39="NO","NO APLICA",MAX(CEILING(($O39*(1-Configuración!$B$2))/Configuración!$B$4,Configuración!$B$6),Configuración!$B$5)) -> 380 | U39: =IF($T39="NO APLICA","NO APLICA",$T39*Configuración!$B$4) -> 4560 | V39: =MAX(CEILING($O39/Configuración!$B$9,Configuración!$B$6),Configuración!$B$5) -> 110 | W39: Activo | X39: 46079
A40: =IF(OR(E40="",F40="",G40=""),"",E40&"-"&F40&"-"&G40&"-"&TEXT(COUNTIFS($E$2:E40,E40,$F$2:F40,F40,$G$2:G40,G40),"000")) -> COC-BAT-ALU-003 | B40: Cocina | C40: Batería | D40: Alumino | E40: =_xlfn.XLOOKUP(B40,Configuración!A:A,Configuración!B:B,"") -> COC | F40: {=IF($C40="","",_xlfn.XLOOKUP(1,(Configuración!D:D=$B40)*(Configuración!E:E=$C40),Configuración!F:F,""))} -> BAT | G40: =IF($D40="","",_xlfn.XLOOKUP($D40,Configuración!H:H,Configuración!I:I,"")) -> ALU | H40: Batería Don beto 9pz | I40: Don beto | J40: Perico | K40: listo | L40: 1820 | M40: =MAX(CEILING(L40/4,10),100) -> 460 | N40: =M40*4 -> 1840 | O40: 2600 | P40: =IF($O40<Configuración!$B$7,"NO","SI") -> SI | Q40: =IF($P40="NO","NO APLICA",MAX(CEILING(($O40*(1-Configuración!$B$2))/Configuración!$B$3,Configuración!$B$6),Configuración!$B$5)) -> 260 | R40: =IF($Q40="NO APLICA","NO APLICA",$Q40*Configuración!$B$3) -> 2080 | S40: =IF($O40<Configuración!$B$8,"NO","SI") -> NO | T40: =IF($S40="NO","NO APLICA",MAX(CEILING(($O40*(1-Configuración!$B$2))/Configuración!$B$4,Configuración!$B$6),Configuración!$B$5)) -> NO APLICA | U40: =IF($T40="NO APLICA","NO APLICA",$T40*Configuración!$B$4) -> NO APLICA | V40: =MAX(CEILING($O40/Configuración!$B$9,Configuración!$B$6),Configuración!$B$5) -> 100 | W40: Activo | X40: 46079
...

Sheet Cotizador
A1: Cotizador rápido (elige un producto)
A3: Producto (Nombre Comercial) | B3: Tripleta gigante 3pz
A4: Código | B4: =IFERROR(INDEX(Lista_Maestra!$A:$A,MATCH($B$3,Lista_Maestra!$H:$H,0)),) -> COC-ARR-ACI-003
A5: Categoría | B5: =IFERROR(INDEX(Lista_Maestra!$B:$B,MATCH($B$3,Lista_Maestra!$H:$H,0)),) -> Cocina
A6: Subcategoría | B6: =IFERROR(INDEX(Lista_Maestra!$C:$C,MATCH($B$3,Lista_Maestra!$H:$H,0)),) -> Arrocera
A7: Precio Contado | B7: =IFERROR(INDEX(Lista_Maestra!$L:$L,MATCH($B$3,Lista_Maestra!$H:$H,0)),) -> 2880
A8: Precio Crédito | B8: =IFERROR(INDEX(Lista_Maestra!$M:$M,MATCH($B$3,Lista_Maestra!$H:$H,0)),) -> 720
A10: Pago semanal 2 meses | B10: =IFERROR(INDEX(Lista_Maestra!$O:$O,MATCH($B$3,Lista_Maestra!$H:$H,0)),) -> 3600
A11: Total 2 meses | B11: =IFERROR(INDEX(Lista_Maestra!$P:$P,MATCH($B$3,Lista_Maestra!$H:$H,0)),) -> SI
A13: Pago semanal 3 meses | B13: =IFERROR(INDEX(Lista_Maestra!$R:$R,MATCH($B$3,Lista_Maestra!$H:$H,0)),) -> 2880
A14: Total 3 meses | B14: =IFERROR(INDEX(Lista_Maestra!$S:$S,MATCH($B$3,Lista_Maestra!$H:$H,0)),) -> SI
A16: Abono semanal (largo plazo) | B16: =IF($B$3="","", MAX(100,ROUNDUP(_xlfn.XLOOKUP($B$3,Tabla_Productos[Nombre_Comercial],Tabla_Productos[Precio_Credito],0)/52,0))) -> 100
A17: Semanas | B17: =IF($B$3="","",MIN(52,ROUNDUP(_xlfn.XLOOKUP($B$3,Tabla_Productos[Nombre_Comercial],Tabla_Productos[Precio_Credito],0)/B16,0))) -> 36
A18: Total largo plazo | B18: =IF($B$3="","",B16*B17) -> 3600

Sheet Inventario_Ruta
A1: Fecha | B1: Ruta | C1: Vendedor | D1: Código | E1: Producto | F1: Cantidad | G1: Tipo_Venta (Crédito/Contado) | H1: Cliente | I1: Notas

Sheet Historial_Cambios
